<?xml version="1.0"?>
<robot name="hyperdog">

  <!-- ================= BASE ================= -->
  <link name="base_link">
    <inertial>
      <origin xyz="0 0 -0.075" rpy="0 0 0"/>
      <mass value="0.5"/>
      <inertia
        ixx="0.001" ixy="0.0" ixz="0.0"
        iyy="0.001" iyz="0.0"
        izz="0.001"/>
    </inertial>

    <visual>
      <geometry>
        <box size="0.2536 0.17 0.05425 "/>
      </geometry>
      <origin xyz="0 0 0.027125" rpy="0 0 0"/>
      <material name="gray">
        <color rgba="0.6 0.6 0.6 1"/>
      </material>
    </visual>

    <collision>
      <geometry>
        <box size="0.2536 0.17 0.05425"/>
      </geometry>
      <origin xyz="0 0 0.06" rpy="0 0 0"/>
    </collision>

  </link>


  <!-- ============ FRONT LEFT HIP ============ -->
  <link name="front_left_hip">
    <inertial>
      <origin xyz="0 0 -0.075" rpy="0 0 0"/>
      <mass value="0.5"/>
      <inertia
       ixx="0.001" ixy="0.0" ixz="0.0"
       iyy="0.001" iyz="0.0"
       izz="0.001"/>
    </inertial>
    <visual>
      <geometry>
        <box size="0.04 0.04 0.04"/>
      </geometry>
      <origin xyz="0 0 0"/>
      <material name="blue">
        <color rgba="0.2 0.2 0.8 1"/>
      </material>
    </visual>
  </link>

  <joint name="front_left_hip_joint" type="revolute">
    <parent link="base_link"/>
    <child link="front_left_hip"/>
    <origin xyz="0.0972 0.0678 0.0171" rpy="0 0 0"/>
    <axis xyz="1 0 0"/>
    <limit lower="-1.5708" upper="1.5708" effort="10" velocity="2"/>
  </joint>

  <!-- ============ THIGH ============ -->
  <link name="front_left_thigh">
    <inertial>
      <origin xyz="0 0 -0.075" rpy="0 0 0"/>
      <mass value="0.5"/>
      <inertia
       ixx="0.001" ixy="0.0" ixz="0.0"
       iyy="0.001" iyz="0.0"
       izz="0.001"/>
    </inertial>  
  
  
    <visual>
      <geometry>
        <box size="0.03 0.03 0.15"/>
      </geometry>
      <origin xyz="0 0 -0.075"/>
      <material name="green">
        <color rgba="0.2 0.8 0.2 1"/>
      </material>
    </visual>
  </link>

  <joint name="front_left_thigh_joint" type="revolute">
    <parent link="front_left_hip"/>
    <child link="front_left_thigh"/>
    <origin xyz="0 0 0" rpy="0 0 0"/>
    <axis xyz="0 1 0"/>
    <limit lower="-1.9199" upper="1.0472" effort="10" velocity="2"/>
  </joint>


  <!-- ============ SHANK ============ -->
  <link name="front_left_shank">
    <inertial>
      <origin xyz="0 0 -0.075" rpy="0 0 0"/>
      <mass value="0.5"/>
      <inertia
       ixx="0.001" ixy="0.0" ixz="0.0"
       iyy="0.001" iyz="0.0"
       izz="0.001"/>
    </inertial>

    <visual>
      <geometry>
        <box size="0.025 0.025 0.15"/>
      </geometry>
      <!-- centro del shank hacia abajo -->
      <origin xyz="0 0 -0.075"/>
      <material name="red"/>
    </visual>

    <collision>
      <geometry>
        <box size="0.025 0.025 0.15"/>
      </geometry>
      <origin xyz="0 0 -0.075"/>
    </collision>

    <surface>
      <friction>
        <ode>
          <mu>1.2</mu>
          <mu2>0.5</mu2>
        </ode>
      </friction>
    </surface>
  </link>

  <joint name="front_left_knee_joint" type="revolute">
    <parent link="front_left_thigh"/>
    <child link="front_left_shank"/>
    <!-- nace al final del thigh -->
    <origin xyz="0 0 -0.15"/>
    <axis xyz="0 1 0"/>  <!-- pitch -->
    <limit lower="-3.0019" upper="-0.4189" effort="10" velocity="2"/>
  </joint>

  <link name="front_left_foot">
    <inertial>
      <mass value="0.05"/>
      <inertia
        ixx="1e-5" ixy="0" ixz="0"
        iyy="1e-5" iyz="0"
        izz="1e-5"/>
    </inertial>

    <collision>
      <geometry>
        <sphere radius="0.015"/>
      </geometry>
    </collision>
  </link>

  <joint name="front_left_foot_joint" type="fixed">
    <parent link="front_left_shank"/>
    <child link="front_left_foot"/>
    <origin xyz="0 0 -0.15"/>
  </joint>

  <!-- ============ FRONT RIGHT HIP ============ -->
  <link name="front_right_hip">
    <inertial>
      <origin xyz="0 0 -0.075" rpy="0 0 0"/>
      <mass value="0.5"/>
      <inertia
       ixx="0.001" ixy="0.0" ixz="0.0"
       iyy="0.001" iyz="0.0"
       izz="0.001"/>
    </inertial>

    <visual>
      <geometry>
        <box size="0.04 0.04 0.04"/>
      </geometry>
      <origin xyz="0 0 0"/>
      <material name="blue">
        <color rgba="0.2 0.2 0.8 1"/>
      </material>
    </visual>
  </link>

  <joint name="front_right_hip_joint" type="revolute">
    <parent link="base_link"/>
    <child link="front_right_hip"/>
    <origin xyz="0.0972 -0.0678 0.0171" rpy="0 0 0"/>
    <axis xyz="-1 0 0"/>
    <limit lower="-1.5708" upper="1.5708" effort="10" velocity="2"/>
  </joint>

  <!-- ============ THIGH ============ -->
  <link name="front_right_thigh">

    <inertial>
      <origin xyz="0 0 -0.075" rpy="0 0 0"/>
      <mass value="0.5"/>
      <inertia
       ixx="0.001" ixy="0.0" ixz="0.0"
       iyy="0.001" iyz="0.0"
       izz="0.001"/>
    </inertial>
    
    <visual>
      <geometry>
        <box size="0.03 0.03 0.15"/>
      </geometry>
      <origin xyz="0 0 -0.075"/>
      <material name="green">
        <color rgba="0.2 0.8 0.2 1"/>
      </material>
    </visual>
  </link>

  <joint name="front_right_thigh_joint" type="revolute">
    <parent link="front_right_hip"/>
    <child link="front_right_thigh"/>
    <origin xyz="0 0 0" rpy="0 0 0"/>
    <axis xyz="0 1 0"/>
    <limit lower="-1.9199" upper="1.0472" effort="10" velocity="2"/>
  </joint>


  <!-- ============ SHANK ============ -->
  <link name="front_right_shank">
    <inertial>
      <origin xyz="0 0 -0.075" rpy="0 0 0"/>
      <mass value="0.5"/>
      <inertia
       ixx="0.001" ixy="0.0" ixz="0.0"
       iyy="0.001" iyz="0.0"
       izz="0.001"/>
    </inertial>
  
    <visual>
      <geometry>
        <box size="0.025 0.025 0.15"/>
      </geometry>
      <!-- centro del shank hacia abajo -->
      <origin xyz="0 0 -0.075"/>
      <material name="red"/>
    </visual>

    <collision>
      <geometry>
        <box size="0.025 0.025 0.15"/>
      </geometry>
      <origin xyz="0 0 -0.075"/>
    </collision>

    <surface>
      <friction>
        <ode>
          <mu>1.2</mu>
          <mu2>0.5</mu2>
        </ode>
      </friction>
    </surface>
  </link>

  <joint name="front_right_knee_joint" type="revolute">
    <parent link="front_right_thigh"/>
    <child link="front_right_shank"/>
    <!-- nace al final del thigh -->
    <origin xyz="0 0 -0.15"/>
    <axis xyz="0 1 0"/>  <!-- pitch -->
    <limit lower="-3.0019" upper="-0.4189" effort="10" velocity="2"/>
  </joint>


  <link name="front_right_foot">
    <inertial>
      <mass value="0.05"/>
      <inertia
        ixx="1e-5" ixy="0" ixz="0"
        iyy="1e-5" iyz="0"
        izz="1e-5"/>
    </inertial>

    <collision>
      <geometry>
        <sphere radius="0.015"/>
      </geometry>
    </collision>
  </link>

  <joint name="front_right_foot_joint" type="fixed">
    <parent link="front_right_shank"/>
    <child link="front_right_foot"/>
    <origin xyz="0 0 -0.15"/>
  </joint>

  <!-- ============ REAR LEFT HIP ============ -->
  <link name="rear_left_hip">
    <inertial>
      <origin xyz="0 0 -0.075" rpy="0 0 0"/>
      <mass value="0.5"/>
      <inertia
       ixx="0.001" ixy="0.0" ixz="0.0"
       iyy="0.001" iyz="0.0"
       izz="0.001"/>
    </inertial>

    <visual>
      <geometry>
        <box size="0.04 0.04 0.04"/>
      </geometry>
      <origin xyz="0 0 0"/>
      <material name="blue">
        <color rgba="0.2 0.2 0.8 1"/>
      </material>
    </visual>
  </link>

  <joint name="rear_left_hip_joint" type="revolute">
    <parent link="base_link"/>
    <child link="rear_left_hip"/>
    <origin xyz="-0.0972 0.0678 0.0171" rpy="0 0 0"/>
    <axis xyz="1 0 0"/>
    <limit lower="-1.5708" upper="1.5708" effort="10" velocity="2"/>
  </joint>

  <!-- ============ THIGH ============ -->
  <link name="rear_left_thigh">
    <inertial>
      <origin xyz="0 0 -0.075" rpy="0 0 0"/>
      <mass value="0.5"/>
      <inertia
       ixx="0.001" ixy="0.0" ixz="0.0"
       iyy="0.001" iyz="0.0"
       izz="0.001"/>
    </inertial>

    <visual>
      <geometry>
        <box size="0.03 0.03 0.15"/>
      </geometry>
      <origin xyz="0 0 -0.075"/>
      <material name="green">
        <color rgba="0.2 0.8 0.2 1"/>
      </material>
    </visual>
  </link>

  <joint name="rear_left_thigh_joint" type="revolute">
    <parent link="rear_left_hip"/>
    <child link="rear_left_thigh"/>
    <origin xyz="0 0 0" rpy="0 0 0"/>
    <axis xyz="0 1 0"/>
    <limit lower="-1.9199" upper="1.0472" effort="10" velocity="2"/>
  </joint>


  <!-- ============ SHANK ============ -->
  <link name="rear_left_shank">
    <inertial>
      <origin xyz="0 0 -0.075" rpy="0 0 0"/>
      <mass value="0.5"/>
      <inertia
       ixx="0.001" ixy="0.0" ixz="0.0"
       iyy="0.001" iyz="0.0"
       izz="0.001"/>
    </inertial>


    <visual>
      <geometry>
        <box size="0.025 0.025 0.15"/>
      </geometry>
      <!-- centro del shank hacia abajo -->
      <origin xyz="0 0 -0.075"/>
      <material name="red"/>
    </visual>


    <collision>
      <geometry>
        <box size="0.025 0.025 0.15"/>
      </geometry>
      <origin xyz="0 0 -0.075"/>
    </collision> 

    <surface>
      <friction>
        <ode>
          <mu>1.2</mu>
          <mu2>0.5</mu2>
        </ode>
      </friction>
    </surface>   
  </link>

  <joint name="rear_left_knee_joint" type="revolute">
    <parent link="rear_left_thigh"/>
    <child link="rear_left_shank"/>
    <!-- nace al final del thigh -->
    <origin xyz="0 0 -0.15"/>
    <axis xyz="0 1 0"/>  <!-- pitch -->
    <limit lower="-3.0019" upper="-0.4189" effort="10" velocity="2"/>
  </joint>

  <link name="rear_left_foot">
    <inertial>
      <mass value="0.05"/>
      <inertia
        ixx="1e-5" ixy="0" ixz="0"
        iyy="1e-5" iyz="0"
        izz="1e-5"/>
    </inertial>
    <collision>
      <geometry>
        <sphere radius="0.015"/>
      </geometry>
    </collision>
  </link>

  <joint name="rear_left_foot_joint" type="fixed">
    <parent link="rear_left_shank"/>
    <child link="rear_left_foot"/>
    <origin xyz="0 0 -0.15"/>
  </joint>
  <!-- ============ REAR RIGHT HIP ============ -->
  <link name="rear_right_hip">
    <inertial>
      <origin xyz="0 0 -0.075" rpy="0 0 0"/>
      <mass value="0.5"/>
      <inertia
       ixx="0.001" ixy="0.0" ixz="0.0"
       iyy="0.001" iyz="0.0"
       izz="0.001"/>
    </inertial>

    <visual>
      <geometry>
        <box size="0.04 0.04 0.04"/>
      </geometry>
      <origin xyz="0 0 0"/>
      <material name="blue">
        <color rgba="0.2 0.2 0.8 1"/>
      </material>
    </visual>
  </link>

  <joint name="rear_right_hip_joint" type="revolute">
    <parent link="base_link"/>
    <child link="rear_right_hip"/>
    <origin xyz="-0.0972 -0.0678 0.0171" rpy="0 0 0"/>
    <axis xyz="-1 0 0"/>
    <limit lower="-1.5708" upper="1.5708" effort="10" velocity="2"/>
  </joint>

  <!-- ============ THIGH ============ -->
  <link name="rear_right_thigh">
    <inertial>
      <origin xyz="0 0 -0.075" rpy="0 0 0"/>
      <mass value="0.5"/>
      <inertia
       ixx="0.001" ixy="0.0" ixz="0.0"
       iyy="0.001" iyz="0.0"
       izz="0.001"/>
    </inertial>

    <visual>
      <geometry>
        <box size="0.03 0.03 0.15"/>
      </geometry>
      <origin xyz="0 0 -0.075"/>
      <material name="green">
        <color rgba="0.2 0.8 0.2 1"/>
      </material>
    </visual>
  </link>

  <joint name="rear_right_thigh_joint" type="revolute">
    <parent link="rear_right_hip"/>
    <child link="rear_right_thigh"/>
    <origin xyz="0 0 0" rpy="0 0 0"/>
    <axis xyz="0 1 0"/>
    <limit lower="-1.9199" upper="1.0472" effort="10" velocity="2"/>
  </joint>


  <!-- ============ SHANK ============ -->
  <link name="rear_right_shank">
    <inertial>
      <origin xyz="0 0 -0.075" rpy="0 0 0"/>
      <mass value="0.5"/>
      <inertia
       ixx="0.001" ixy="0.0" ixz="0.0"
       iyy="0.001" iyz="0.0"
       izz="0.001"/>
    </inertial>
  
    <visual>
      <geometry>
        <box size="0.025 0.025 0.15"/>
      </geometry>
      <!-- centro del shank hacia abajo -->
      <origin xyz="0 0 -0.075"/>
      <material name="red"/>
    </visual>


    <collision>
      <geometry>
        <box size="0.025 0.025 0.15"/>
      </geometry>
      <origin xyz="0 0 -0.075"/>
    </collision>

    <surface>
      <friction>
        <ode>
          <mu>1.2</mu>
          <mu2>0.5</mu2>
        </ode>
      </friction>
    </surface>

  </link>
  
  <joint name="rear_right_knee_joint" type="revolute">
    <parent link="rear_right_thigh"/>
    <child link="rear_right_shank"/>
    <!-- nace al final del thigh -->
    <origin xyz="0 0 -0.15"/>
    <axis xyz="0 1 0"/>  <!-- pitch -->
    <limit lower="-3.0019" upper="-0.4189" effort="10" velocity="2"/>
  </joint>

  <link name="rear_right_foot">
    <inertial>
      <mass value="0.05"/>
      <inertia
        ixx="1e-5" ixy="0" ixz="0"
        iyy="1e-5" iyz="0"
        izz="1e-5"/>
    </inertial>
    <collision>
      <geometry>
        <sphere radius="0.015"/>
      </geometry>
    </collision>
  </link>

  <joint name="rear_right_foot_joint" type="fixed">
    <parent link="rear_right_shank"/>
    <child link="rear_right_foot"/>
    <origin xyz="0 0 -0.15"/>
  </joint>
</robot>